Traceback (most recent call last):
  File "C:\Users\kovor\Anaconda3\envs\prova\lib\site-packages\jupyter_cache\executors\utils.py", line 51, in single_nb_execution
    executenb(
  File "C:\Users\kovor\Anaconda3\envs\prova\lib\site-packages\nbclient\client.py", line 1204, in execute
    return NotebookClient(nb=nb, resources=resources, km=km, **kwargs).execute()
  File "C:\Users\kovor\Anaconda3\envs\prova\lib\site-packages\nbclient\util.py", line 84, in wrapped
    return just_run(coro(*args, **kwargs))
  File "C:\Users\kovor\Anaconda3\envs\prova\lib\site-packages\nbclient\util.py", line 62, in just_run
    return loop.run_until_complete(coro)
  File "C:\Users\kovor\Anaconda3\envs\prova\lib\asyncio\base_events.py", line 647, in run_until_complete
    return future.result()
  File "C:\Users\kovor\Anaconda3\envs\prova\lib\site-packages\nbclient\client.py", line 663, in async_execute
    await self.async_execute_cell(
  File "C:\Users\kovor\Anaconda3\envs\prova\lib\site-packages\nbclient\client.py", line 965, in async_execute_cell
    await self._check_raise_for_error(cell, cell_index, exec_reply)
  File "C:\Users\kovor\Anaconda3\envs\prova\lib\site-packages\nbclient\client.py", line 862, in _check_raise_for_error
    raise CellExecutionError.from_cell_and_msg(cell, exec_reply_content)
nbclient.exceptions.CellExecutionError: An error occurred while executing the following cell:
------------------
from pySurf.data2D_class import Data2D
------------------

[1;31m---------------------------------------------------------------------------[0m
[1;31mModuleNotFoundError[0m                       Traceback (most recent call last)
[1;32m<ipython-input-2-10b09464274b>[0m in [0;36m<module>[1;34m[0m
[1;32m----> 1[1;33m [1;32mfrom[0m [0mpySurf[0m[1;33m.[0m[0mdata2D_class[0m [1;32mimport[0m [0mData2D[0m[1;33m[0m[1;33m[0m[0m
[0m
[1;32m~\Anaconda3\lib\site-packages\pyxsurf-1.5.1-py3.8.egg\pySurf\data2D_class.py[0m in [0;36m<module>[1;34m[0m
[0;32m     20[0m                            transpose_data, get_stats)
[0;32m     21[0m [1;32mfrom[0m [0mpySurf[0m[1;33m.[0m[0mpoints[0m [1;32mimport[0m [0mmatrix_to_points2[0m[1;33m,[0m [0mpoints_autoresample[0m[1;33m[0m[1;33m[0m[0m
[1;32m---> 22[1;33m from pySurf.psd2d import (plot_psd2d, plot_rms_power, psd2d, psd2d_analysis,
[0m[0;32m     23[0m                           rms_power)
[0;32m     24[0m [1;32mfrom[0m [0mpySurf[0m[1;33m.[0m[0mreaders[0m[1;33m.[0m[0mformat_reader[0m [1;32mimport[0m [0mauto_reader[0m[1;33m[0m[1;33m[0m[0m

[1;32m~\Anaconda3\lib\site-packages\pyxsurf-1.5.1-py3.8.egg\pySurf\psd2d.py[0m in [0;36m<module>[1;34m[0m
[0;32m     12[0m [1;32mfrom[0m [0mpySurf[0m[1;33m.[0m[0moutliers2d[0m [1;32mimport[0m [0mremove_outliers2d[0m[1;33m[0m[1;33m[0m[0m
[0;32m     13[0m [1;32mfrom[0m [0mmatplotlib[0m[1;33m.[0m[0mcolors[0m [1;32mimport[0m [0mLogNorm[0m[1;33m[0m[1;33m[0m[0m
[1;32m---> 14[1;33m [1;32mfrom[0m [0mutilities[0m[1;33m.[0m[0mimaging[0m [1;32mimport[0m [0mfitting[0m [1;32mas[0m [0mfit[0m[1;33m[0m[1;33m[0m[0m
[0m[0;32m     15[0m [1;31m# from IPython.display import display[0m[1;33m[0m[1;33m[0m[1;33m[0m[0m
[0;32m     16[0m [1;32mfrom[0m [0mplotting[0m[1;33m.[0m[0mfignumber[0m [1;32mimport[0m [0mfignumber[0m[1;33m[0m[1;33m[0m[0m

[1;31mModuleNotFoundError[0m: No module named 'utilities.imaging'
ModuleNotFoundError: No module named 'utilities.imaging'

